<?xml version="1.0" encoding="UTF-8"?>
<testng-results skipped="1" failed="1" ignored="0" total="3" passed="1">
  <reporter-output>
  </reporter-output>
  <suite name="Default suite" duration-ms="39" started-at="2018-10-13T04:35:06Z" finished-at="2018-10-13T04:35:06Z">
    <groups>
      <group name="smoke">
        <method signature="Example.Test2()[pri:2, instance:DEmo.Example@7c0e2abd]" name="Test2" class="DEmo.Example"/>
      </group> <!-- smoke -->
      <group name="smoke,reg">
        <method signature="Example.Test1()[pri:1, instance:DEmo.Example@7c0e2abd]" name="Test1" class="DEmo.Example"/>
      </group> <!-- smoke,reg -->
    </groups>
    <test name="Default test" duration-ms="39" started-at="2018-10-13T04:35:06Z" finished-at="2018-10-13T04:35:06Z">
      <class name="DEmo.Example">
        <test-method status="PASS" signature="Test1()[pri:1, instance:DEmo.Example@7c0e2abd]" name="Test1" duration-ms="11" started-at="2018-10-13T10:05:06Z" finished-at="2018-10-13T10:05:06Z">
          <reporter-output>
          </reporter-output>
        </test-method> <!-- Test1 -->
        <test-method status="FAIL" signature="Test2()[pri:2, instance:DEmo.Example@7c0e2abd]" name="Test2" duration-ms="2" started-at="2018-10-13T10:05:06Z" finished-at="2018-10-13T10:05:06Z">
          <exception class="java.lang.AssertionError">
            <message>
              <![CDATA[expected [true] but found [false]]]>
            </message>
            <full-stacktrace>
              <![CDATA[java.lang.AssertionError: expected [true] but found [false]
	at org.testng.Assert.fail(Assert.java:93)
	at org.testng.Assert.failNotEquals(Assert.java:512)
	at org.testng.Assert.assertEqualsImpl(Assert.java:134)
	at org.testng.Assert.assertEquals(Assert.java:115)
	at org.testng.Assert.assertEquals(Assert.java:304)
	at org.testng.Assert.assertEquals(Assert.java:314)
	at DEmo.Example.Test2(Example.java:19)
	at sun.reflect.NativeMethodAccessorImpl.invoke0(Native Method)
	at sun.reflect.NativeMethodAccessorImpl.invoke(Unknown Source)
	at sun.reflect.DelegatingMethodAccessorImpl.invoke(Unknown Source)
	at java.lang.reflect.Method.invoke(Unknown Source)
	at org.testng.internal.MethodInvocationHelper.invokeMethod(MethodInvocationHelper.java:108)
	at org.testng.internal.Invoker.invokeMethod(Invoker.java:661)
	at org.testng.internal.Invoker.invokeTestMethod(Invoker.java:869)
	at org.testng.internal.Invoker.invokeTestMethods(Invoker.java:1193)
	at org.testng.internal.TestMethodWorker.invokeTestMethods(TestMethodWorker.java:126)
	at org.testng.internal.TestMethodWorker.run(TestMethodWorker.java:109)
	at org.testng.TestRunner.privateRun(TestRunner.java:744)
	at org.testng.TestRunner.run(TestRunner.java:602)
	at org.testng.SuiteRunner.runTest(SuiteRunner.java:380)
	at org.testng.SuiteRunner.runSequentially(SuiteRunner.java:375)
	at org.testng.SuiteRunner.privateRun(SuiteRunner.java:340)
	at org.testng.SuiteRunner.run(SuiteRunner.java:289)
	at org.testng.SuiteRunnerWorker.runSuite(SuiteRunnerWorker.java:52)
	at org.testng.SuiteRunnerWorker.run(SuiteRunnerWorker.java:86)
	at org.testng.TestNG.runSuitesSequentially(TestNG.java:1301)
	at org.testng.TestNG.runSuitesLocally(TestNG.java:1226)
	at org.testng.TestNG.runSuites(TestNG.java:1144)
	at org.testng.TestNG.run(TestNG.java:1115)
	at org.testng.remote.AbstractRemoteTestNG.run(AbstractRemoteTestNG.java:132)
	at org.testng.remote.RemoteTestNG.initAndRun(RemoteTestNG.java:230)
	at org.testng.remote.RemoteTestNG.main(RemoteTestNG.java:76)
]]>
            </full-stacktrace>
          </exception> <!-- java.lang.AssertionError -->
          <reporter-output>
          </reporter-output>
        </test-method> <!-- Test2 -->
        <test-method status="SKIP" signature="Test3()[pri:3, instance:DEmo.Example@7c0e2abd]" name="Test3" duration-ms="0" depends-on-groups="smoke" started-at="2018-10-13T10:05:06Z" finished-at="2018-10-13T10:05:06Z">
          <exception class="java.lang.Throwable">
            <message>
              <![CDATA[Method Example.Test3()[pri:3, instance:DEmo.Example@7c0e2abd] depends on not successfully finished methods in group "smoke"]]>
            </message>
            <full-stacktrace>
              <![CDATA[java.lang.Throwable: Method Example.Test3()[pri:3, instance:DEmo.Example@7c0e2abd] depends on not successfully finished methods in group "smoke"
	at org.testng.internal.Invoker.invokeTestMethods(Invoker.java:1084)
	at org.testng.internal.TestMethodWorker.invokeTestMethods(TestMethodWorker.java:126)
	at org.testng.internal.TestMethodWorker.run(TestMethodWorker.java:109)
	at org.testng.TestRunner.privateRun(TestRunner.java:744)
	at org.testng.TestRunner.run(TestRunner.java:602)
	at org.testng.SuiteRunner.runTest(SuiteRunner.java:380)
	at org.testng.SuiteRunner.runSequentially(SuiteRunner.java:375)
	at org.testng.SuiteRunner.privateRun(SuiteRunner.java:340)
	at org.testng.SuiteRunner.run(SuiteRunner.java:289)
	at org.testng.SuiteRunnerWorker.runSuite(SuiteRunnerWorker.java:52)
	at org.testng.SuiteRunnerWorker.run(SuiteRunnerWorker.java:86)
	at org.testng.TestNG.runSuitesSequentially(TestNG.java:1301)
	at org.testng.TestNG.runSuitesLocally(TestNG.java:1226)
	at org.testng.TestNG.runSuites(TestNG.java:1144)
	at org.testng.TestNG.run(TestNG.java:1115)
	at org.testng.remote.AbstractRemoteTestNG.run(AbstractRemoteTestNG.java:132)
	at org.testng.remote.RemoteTestNG.initAndRun(RemoteTestNG.java:230)
	at org.testng.remote.RemoteTestNG.main(RemoteTestNG.java:76)
]]>
            </full-stacktrace>
          </exception> <!-- java.lang.Throwable -->
          <reporter-output>
          </reporter-output>
        </test-method> <!-- Test3 -->
      </class> <!-- DEmo.Example -->
    </test> <!-- Default test -->
  </suite> <!-- Default suite -->
</testng-results>
